<robot name="humanoid_v1">
<link name="base_link"></link>
<joint name="base_link_to_base" type="fixed">
<parent link="base_link"/>
<child link="base" />
<origin rpy="0.0 0 0" xyz="0 0 0"/>
</joint>
<link name="base">
<!-- Shapes for part_2 -->
<collision>
<origin xyz="0.04 1.88738e-17 -0.056" rpy="-3.14159 -1.5708 0" />
<geometry>
<cylinder length="0.022" radius="0.036" />
</geometry>
</collision>
<!-- Shapes for part_1 -->
<collision>
<origin xyz="0.034 0 -0.056" rpy="-3.14159 -1.5708 0" />
<geometry>
<cylinder length="0.018" radius="0.024" />
</geometry>
</collision>
<!-- Shapes for extrusion_400mm -->
<collision>
<origin xyz="0.065 -0.06 0.21" rpy="0 -0 0" />
<geometry>
<box size="0.02 0.02 0.4" />
</geometry>
</collision>
<collision>
<origin xyz="-0.065 -0.06 0.21" rpy="0 -0 0" />
<geometry>
<box size="0.02 0.02 0.4" />
</geometry>
</collision>
<!-- Shapes for motor_shell -->
<collision>
<origin xyz="0.035 0 -0.056" rpy="-0 -1.5708 0" />
<geometry>
<cylinder length="0.03" radius="0.045" />
</geometry>
</collision>
<!-- Shapes for motor_shell -->
<collision>
<origin xyz="-0.035 6.93889e-18 -0.056" rpy="-3.14159 -1.5708 0" />
<geometry>
<cylinder length="0.03" radius="0.045" />
</geometry>
</collision>
<!-- Shapes for housing -->
<collision>
<origin xyz="-0.066 6.93889e-18 -0.056" rpy="-3.14159 -1.5708 0" />
<geometry>
<cylinder length="0.02" radius="0.045" />
</geometry>
</collision>
<!-- Shapes for cycloidal_disk -->
<!-- Shapes for housing -->
<collision>
<origin xyz="0.066 0 -0.056" rpy="-0 -1.5708 0" />
<geometry>
<cylinder length="0.02" radius="0.045" />
</geometry>
</collision>
<!-- Shapes for extrusion_150mm -->
<collision>
<origin xyz="0 0.06 0" rpy="0 -0 0" />
<geometry>
<box size="0.15 0.02 0.02" />
</geometry>
</collision>
<collision>
<origin xyz="0 -0.06 0" rpy="0 -0 0" />
<geometry>
<box size="0.15 0.02 0.02" />
</geometry>
</collision>
<!-- Shapes for extrusion_100mm -->
<collision>
<origin xyz="0.065 0 0" rpy="0 -0 0" />
<geometry>
<box size="0.02 0.1 0.02" />
</geometry>
</collision>
<collision>
<origin xyz="-0.065 0 0" rpy="0 -0 0" />
<geometry>
<box size="0.02 0.1 0.02" />
</geometry>
</collision>
<!-- Shapes for housing -->
<collision>
<origin xyz="-0.066 6.93889e-18 -0.056" rpy="-3.14159 -1.5708 0" />
<geometry>
<cylinder length="0.02" radius="0.045" />
</geometry>
</collision>
<!-- Shapes for cycloidal_disk -->
<!-- Shapes for extrusion_150mm -->
<collision>
<origin xyz="0 0.06 0" rpy="0 -0 0" />
<geometry>
<box size="0.15 0.02 0.02" />
</geometry>
</collision>
<collision>
<origin xyz="0 -0.06 0" rpy="0 -0 0" />
<geometry>
<box size="0.15 0.02 0.02" />
</geometry>
</collision>
<!-- Shapes for part_2 -->
<collision>
<origin xyz="-0.04 -1.56752e-17 -0.056" rpy="4.17605e-18 -1.5708 0" />
<geometry>
<cylinder length="0.022" radius="0.036" />
</geometry>
</collision>
<!-- Shapes for housing -->
<collision>
<origin xyz="-0.066 6.93889e-18 -0.056" rpy="-3.14159 -1.5708 0" />
<geometry>
<cylinder length="0.02" radius="0.045" />
</geometry>
</collision>
<!-- Shapes for extrusion_400mm -->
<collision>
<origin xyz="0.065 -0.06 0.21" rpy="0 -0 0" />
<geometry>
<box size="0.02 0.02 0.4" />
</geometry>
</collision>
<collision>
<origin xyz="-0.065 -0.06 0.21" rpy="0 -0 0" />
<geometry>
<box size="0.02 0.02 0.4" />
</geometry>
</collision>
<!-- Shapes for housing -->
<collision>
<origin xyz="0.066 0 -0.056" rpy="-0 -1.5708 0" />
<geometry>
<cylinder length="0.02" radius="0.045" />
</geometry>
</collision>
<!-- Shapes for cycloidal_disk -->
<!-- Shapes for extrusion_100mm -->
<collision>
<origin xyz="0.065 0 0" rpy="0 -0 0" />
<geometry>
<box size="0.02 0.1 0.02" />
</geometry>
</collision>
<collision>
<origin xyz="-0.065 0 0" rpy="0 -0 0" />
<geometry>
<box size="0.02 0.1 0.02" />
</geometry>
</collision>
<!-- Shapes for cycloidal_disk -->
<!-- Shapes for part_1 -->
<collision>
<origin xyz="-0.034 0 -0.056" rpy="-0 -1.5708 0" />
<geometry>
<cylinder length="0.018" radius="0.024" />
</geometry>
</collision>
<!-- Shapes for housing -->
<collision>
<origin xyz="0.066 0 -0.056" rpy="-0 -1.5708 0" />
<geometry>
<cylinder length="0.02" radius="0.045" />
</geometry>
</collision>
<visual>
<origin xyz="0 0 0" rpy="0 -0 0" />
<geometry>
<mesh filename="package:///base_visual.stl"/>
</geometry>
<material name="base_material">
<color rgba="0.8 0.8 0.8 1.0"/>
</material>
</visual>
<collision>
<origin xyz="0 0 0" rpy="0 -0 0" />
<geometry>
<mesh filename="package:///base_collision.stl"/>
</geometry>
<material name="base_material">
<color rgba="0.5 0.5 0.5 1.0"/>
</material>
</collision>
<inertial>
<origin xyz="2.1706e-17 -0.0296036 0.154811" rpy="0 0 0"/>
<mass value="5.09484" />
<inertia ixx="0.140764" ixy="0.00418147"  ixz="4.66207e-17" iyy="0.230113" iyz="0.0155201" izz="0.0977939" />
</inertial>
</link>

<link name="upperlegx">
<!-- Shapes for part_1 -->
<collision>
<origin xyz="0.0315 -6.45678e-15 -0.052" rpy="-1.5708 2.22937e-13 1.5708" />
<geometry>
<cylinder length="0.018" radius="0.024" />
</geometry>
</collision>
<!-- Shapes for cycloidal_disk -->
<!-- Shapes for cycloidal_disk -->
<!-- Shapes for housing -->
<collision>
<origin xyz="-0.0005 -6.25139e-15 -0.052" rpy="1.5708 3.60869e-14 1.5708" />
<geometry>
<cylinder length="0.02" radius="0.045" />
</geometry>
</collision>
<!-- Shapes for motor_shell -->
<collision>
<origin xyz="0.0305 -7.52653e-15 -0.052" rpy="1.5708 3.60869e-14 1.5708" />
<geometry>
<cylinder length="0.03" radius="0.045" />
</geometry>
</collision>
<!-- Shapes for housing -->
<collision>
<origin xyz="-0.0005 -6.25139e-15 -0.052" rpy="1.5708 3.60869e-14 1.5708" />
<geometry>
<cylinder length="0.02" radius="0.045" />
</geometry>
</collision>
<!-- Shapes for part_2 -->
<collision>
<origin xyz="0.0255 -6.48204e-15 -0.052" rpy="-1.5708 2.00622e-13 1.5708" />
<geometry>
<cylinder length="0.022" radius="0.036" />
</geometry>
</collision>
<!-- Shapes for housing -->
<collision>
<origin xyz="-0.0005 -6.25139e-15 -0.052" rpy="1.5708 3.60869e-14 1.5708" />
<geometry>
<cylinder length="0.02" radius="0.045" />
</geometry>
</collision>
<visual>
<origin xyz="0 0 0" rpy="0 -0 0" />
<geometry>
<mesh filename="package:///upperlegx_visual.stl"/>
</geometry>
<material name="upperlegx_material">
<color rgba="0.8 0.8 0.8 1.0"/>
</material>
</visual>
<collision>
<origin xyz="0 0 0" rpy="0 -0 0" />
<geometry>
<mesh filename="package:///upperlegx_collision.stl"/>
</geometry>
<material name="upperlegx_material">
<color rgba="0.5 0.5 0.5 1.0"/>
</material>
</collision>
<inertial>
<origin xyz="0.0134137 -2.72625e-09 -0.0503059" rpy="0 0 0"/>
<mass value="0.732188" />
<inertia ixx="0.000759087" ixy="1.06686e-07"  ixz="1.66386e-05" iyy="0.000618258" iyz="-1.55325e-11" izz="0.000568045" />
</inertial>
</link>

<link name="upperlegy">
<!-- Shapes for cycloidal_disk -->
<!-- Shapes for part_2 -->
<collision>
<origin xyz="-9.63409e-15 0.099 -0.0175" rpy="-1.5708 -1.68759e-14 7.69755e-15" />
<geometry>
<cylinder length="0.022" radius="0.036" />
</geometry>
</collision>
<!-- Shapes for housing -->
<collision>
<origin xyz="-9.84879e-15 0.125 -0.0175" rpy="1.5708 -1.57772e-30 7.69755e-15" />
<geometry>
<cylinder length="0.02" radius="0.045" />
</geometry>
</collision>
<!-- Shapes for housing -->
<collision>
<origin xyz="-9.84879e-15 0.125 -0.0175" rpy="1.5708 -1.57772e-30 7.69755e-15" />
<geometry>
<cylinder length="0.02" radius="0.045" />
</geometry>
</collision>
<!-- Shapes for part_1 -->
<collision>
<origin xyz="-9.58944e-15 0.093 -0.0175" rpy="-1.5708 -1.57772e-30 7.69755e-15" />
<geometry>
<cylinder length="0.018" radius="0.024" />
</geometry>
</collision>
<!-- Shapes for motor_shell -->
<collision>
<origin xyz="-9.61016e-15 0.094 -0.0175" rpy="1.5708 -1.57772e-30 7.69755e-15" />
<geometry>
<cylinder length="0.03" radius="0.045" />
</geometry>
</collision>
<!-- Shapes for cycloidal_disk -->
<!-- Shapes for housing -->
<collision>
<origin xyz="-9.84879e-15 0.125 -0.0175" rpy="1.5708 -1.57772e-30 7.69755e-15" />
<geometry>
<cylinder length="0.02" radius="0.045" />
</geometry>
</collision>
<visual>
<origin xyz="0 0 0" rpy="0 -0 0" />
<geometry>
<mesh filename="package:///upperlegy_visual.stl"/>
</geometry>
<material name="upperlegy_material">
<color rgba="0.8 0.8 0.8 1.0"/>
</material>
</visual>
<collision>
<origin xyz="0 0 0" rpy="0 -0 0" />
<geometry>
<mesh filename="package:///upperlegy_collision.stl"/>
</geometry>
<material name="upperlegy_material">
<color rgba="0.5 0.5 0.5 1.0"/>
</material>
</collision>
<inertial>
<origin xyz="-3.43845e-09 0.109524 -0.0175" rpy="0 0 0"/>
<mass value="0.65579" />
<inertia ixx="0.000501677" ixy="-1.06691e-07"  ixz="-1.61313e-12" iyy="0.000618053" iyz="2.08745e-12" izz="0.000501763" />
</inertial>
</link>

<link name="upperlegz">
<!-- Shapes for extrusion__length_0.2+meter -->
<collision>
<origin xyz="-0.02 2.84367e-20 0.108" rpy="-3.14159 -1.5708 0" />
<geometry>
<box size="0.2 0.02 0.02" />
</geometry>
</collision>
<!-- Shapes for motor_shell -->
<collision>
<origin xyz="-0.011 -3.82134e-19 0.288" rpy="-0 -1.5708 0" />
<geometry>
<cylinder length="0.03" radius="0.045" />
</geometry>
</collision>
<!-- Shapes for cycloidal_disk -->
<!-- Shapes for cycloidal_disk -->
<!-- Shapes for part_2 -->
<collision>
<origin xyz="-0.006 -3.20607e-18 0.288" rpy="-3.14159 -1.5708 0" />
<geometry>
<cylinder length="0.022" radius="0.036" />
</geometry>
</collision>
<!-- Shapes for housing -->
<collision>
<origin xyz="0.02 -3.82134e-19 0.288" rpy="-0 -1.5708 0" />
<geometry>
<cylinder length="0.02" radius="0.045" />
</geometry>
</collision>
<!-- Shapes for extrusion__length_0.2+meter -->
<collision>
<origin xyz="0.02 -5.44764e-19 0.108" rpy="-3.14159 -1.5708 0" />
<geometry>
<box size="0.2 0.02 0.02" />
</geometry>
</collision>
<!-- Shapes for housing -->
<collision>
<origin xyz="0.02 -3.82134e-19 0.288" rpy="-0 -1.5708 0" />
<geometry>
<cylinder length="0.02" radius="0.045" />
</geometry>
</collision>
<!-- Shapes for housing -->
<collision>
<origin xyz="0.02 -3.82134e-19 0.288" rpy="-0 -1.5708 0" />
<geometry>
<cylinder length="0.02" radius="0.045" />
</geometry>
</collision>
<!-- Shapes for part_1 -->
<collision>
<origin xyz="-0.012 1.06091e-17 0.288" rpy="-3.14159 -1.5708 0" />
<geometry>
<cylinder length="0.018" radius="0.024" />
</geometry>
</collision>
<visual>
<origin xyz="0 0 0" rpy="0 -0 0" />
<geometry>
<mesh filename="package:///upperlegz_visual.stl"/>
</geometry>
<material name="upperlegz_material">
<color rgba="0.8 0.8 0.8 1.0"/>
</material>
</visual>
<collision>
<origin xyz="0 0 0" rpy="0 -0 0" />
<geometry>
<mesh filename="package:///upperlegz_collision.stl"/>
</geometry>
<material name="upperlegz_material">
<color rgba="0.5 0.5 0.5 1.0"/>
</material>
</collision>
<inertial>
<origin xyz="0.00580914 -0.000686366 0.226874" rpy="0 0 0"/>
<mass value="1.07815" />
<inertia ixx="0.0108106" ixy="1.34037e-05"  ixz="-0.000206513" iyy="0.0107895" iyz="5.82774e-07" izz="0.000764981" />
</inertial>
</link>

<link name="lowerlegx">
<!-- Shapes for cycloidal_disk -->
<!-- Shapes for housing -->
<collision>
<origin xyz="-3.10811e-30 0.123 0.037" rpy="1.5708 1.5708 0" />
<geometry>
<cylinder length="0.02" radius="0.045" />
</geometry>
</collision>
<!-- Shapes for housing -->
<collision>
<origin xyz="-3.10811e-30 0.123 0.037" rpy="1.5708 1.5708 0" />
<geometry>
<cylinder length="0.02" radius="0.045" />
</geometry>
</collision>
<!-- Shapes for housing -->
<collision>
<origin xyz="-3.10811e-30 0.123 0.037" rpy="1.5708 1.5708 0" />
<geometry>
<cylinder length="0.02" radius="0.045" />
</geometry>
</collision>
<!-- Shapes for motor_shell -->
<collision>
<origin xyz="-3.01029e-30 0.092 0.037" rpy="1.5708 1.5708 0" />
<geometry>
<cylinder length="0.03" radius="0.045" />
</geometry>
</collision>
<!-- Shapes for cycloidal_disk -->
<visual>
<origin xyz="0 0 0" rpy="0 -0 0" />
<geometry>
<mesh filename="package:///lowerlegx_visual.stl"/>
</geometry>
<material name="lowerlegx_material">
<color rgba="0.8 0.8 0.8 1.0"/>
</material>
</visual>
<collision>
<origin xyz="0 0 0" rpy="0 -0 0" />
<geometry>
<mesh filename="package:///lowerlegx_collision.stl"/>
</geometry>
<material name="lowerlegx_material">
<color rgba="0.5 0.5 0.5 1.0"/>
</material>
</collision>
<inertial>
<origin xyz="-3.08432e-11 0.0901691 0.0312672" rpy="0 0 0"/>
<mass value="0.371026" />
<inertia ixx="0.000562525" ixy="2.2725e-12"  ixz="-5.15705e-09" iyy="0.000284979" iyz="-0.000126255" izz="0.000498725" />
</inertial>
</link>

<link name="lowerlegz">
<!-- Shapes for housing -->
<collision>
<origin xyz="-0.0015 -2.36789e-18 -0.2" rpy="3.14159 1.5708 0" />
<geometry>
<cylinder length="0.02" radius="0.045" />
</geometry>
</collision>
<!-- Shapes for housing -->
<collision>
<origin xyz="-0.0015 -2.36789e-18 -0.2" rpy="3.14159 1.5708 0" />
<geometry>
<cylinder length="0.02" radius="0.045" />
</geometry>
</collision>
<!-- Shapes for cycloidal_disk -->
<!-- Shapes for extrusion__length_0.15+meter -->
<collision>
<origin xyz="2.77556e-17 1.6263e-19 -0.085" rpy="-0 1.5708 0" />
<geometry>
<box size="0.15 0.02 0.02" />
</geometry>
</collision>
<!-- Shapes for housing -->
<collision>
<origin xyz="-0.0015 -2.36789e-18 -0.2" rpy="3.14159 1.5708 0" />
<geometry>
<cylinder length="0.02" radius="0.045" />
</geometry>
</collision>
<!-- Shapes for cycloidal_disk -->
<!-- Shapes for motor_shell -->
<collision>
<origin xyz="-0.0325 -2.36789e-18 -0.2" rpy="3.14159 1.5708 0" />
<geometry>
<cylinder length="0.03" radius="0.045" />
</geometry>
</collision>
<visual>
<origin xyz="0 0 0" rpy="0 -0 0" />
<geometry>
<mesh filename="package:///lowerlegz_visual.stl"/>
</geometry>
<material name="lowerlegz_material">
<color rgba="0.8 0.8 0.8 1.0"/>
</material>
</visual>
<collision>
<origin xyz="0 0 0" rpy="0 -0 0" />
<geometry>
<mesh filename="package:///lowerlegz_collision.stl"/>
</geometry>
<material name="lowerlegz_material">
<color rgba="0.5 0.5 0.5 1.0"/>
</material>
</collision>
<inertial>
<origin xyz="-0.0111152 -7.92857e-12 -0.158926" rpy="0 0 0"/>
<mass value="0.457786" />
<inertia ixx="0.00222732" ixy="-2.17139e-12"  ixz="-0.000217459" iyy="0.00224323" iyz="5.16092e-09" izz="0.000243554" />
</inertial>
</link>

<link name="feetx">
<!-- Shapes for feet -->
<collision>
<origin xyz="0 0 0" rpy="-1.5708 -1.5708 0" />
<geometry>
<sphere radius="0.01" />
</geometry>
</collision>
<visual>
<origin xyz="0 0 0" rpy="0 -0 0" />
<geometry>
<mesh filename="package:///feetx_visual.stl"/>
</geometry>
<material name="feetx_material">
<color rgba="0.8 0.8 0.8 1.0"/>
</material>
</visual>
<inertial>
<origin xyz="0.0223276 -0.0258701 0.00228741" rpy="0 0 0"/>
<mass value="0.0599595" />
<inertia ixx="3.79266e-05" ixy="1.67086e-05"  ixz="-8.09396e-06" iyy="3.35016e-05" iyz="5.30576e-06" izz="5.55391e-05" />
</inertial>
</link>

<link name="feety">
<!-- Shapes for housing -->
<collision>
<origin xyz="8.32667e-19 -5.82867e-18 -0.017" rpy="3.14159 -1.66533e-16 -2.52117e-30" />
<geometry>
<cylinder length="0.02" radius="0.045" />
</geometry>
</collision>
<!-- Shapes for cycloidal_disk -->
<!-- Shapes for housing -->
<collision>
<origin xyz="8.32667e-19 -5.82867e-18 -0.017" rpy="3.14159 -1.66533e-16 -2.52117e-30" />
<geometry>
<cylinder length="0.02" radius="0.045" />
</geometry>
</collision>
<!-- Shapes for housing -->
<collision>
<origin xyz="8.32667e-19 -5.82867e-18 -0.017" rpy="3.14159 -1.66533e-16 -2.52117e-30" />
<geometry>
<cylinder length="0.02" radius="0.045" />
</geometry>
</collision>
<!-- Shapes for cycloidal_disk -->
<!-- Shapes for motor_shell -->
<collision>
<origin xyz="2.55351e-18 -1.78746e-17 -0.048" rpy="3.14159 -1.66533e-16 -2.52117e-30" />
<geometry>
<cylinder length="0.03" radius="0.045" />
</geometry>
</collision>
<visual>
<origin xyz="0 0 0" rpy="0 -0 0" />
<geometry>
<mesh filename="package:///feety_visual.stl"/>
</geometry>
<material name="feety_material">
<color rgba="0.8 0.8 0.8 1.0"/>
</material>
</visual>
<collision>
<origin xyz="0 0 0" rpy="0 -0 0" />
<geometry>
<mesh filename="package:///feety_collision.stl"/>
</geometry>
<material name="feety_material">
<color rgba="0.5 0.5 0.5 1.0"/>
</material>
</collision>
<inertial>
<origin xyz="-1.15671e-09 0.0251333 -0.0557187" rpy="0 0 0"/>
<mass value="1.93667" />
<inertia ixx="0.0122302" ixy="-5.21342e-09"  ixz="-3.90299e-08" iyy="0.0123883" iyz="-0.00171265" izz="0.00277728" />
</inertial>
</link>

<joint name="feet_y_r" type="revolute">
<origin xyz="0.048 -0.0398251 0.0140842" rpy="-3.14159 1.5708 0" />
<parent link="feetx" />
<child link="feety" />
<axis xyz="0 0 1"/>
<limit effort="1" velocity="20" lower="-0.261799" upper="0.261799"/>
<joint_properties friction="0.0"/>
</joint>

<joint name="feet_x_r" type="revolute">
<origin xyz="0.0155 -2.36789e-18 -0.2" rpy="1.5708 -5.24209e-17 -1.5708" />
<parent link="lowerlegz" />
<child link="feetx" />
<axis xyz="0 0 1"/>
<limit effort="1" velocity="20" lower="-0.785398" upper="0.785398"/>
<joint_properties friction="0.0"/>
</joint>

<joint name="lowerleg_z_r" type="revolute">
<origin xyz="-3.15544e-30 0.14 0.037" rpy="1.5708 -1.5708 0" />
<parent link="lowerlegx" />
<child link="lowerlegz" />
<axis xyz="0 0 1"/>
<limit effort="1" velocity="20" lower="-0.785398" upper="0.785398"/>
<joint_properties friction="0.0"/>
</joint>

<joint name="lowerleg_x_r" type="revolute">
<origin xyz="0.037 9.07461e-19 0.288" rpy="1.5708 9.49411e-16 -1.5708" />
<parent link="upperlegz" />
<child link="lowerlegx" />
<axis xyz="0 0 1"/>
<limit effort="1" velocity="20" lower="-0.174533" upper="1.74533"/>
<joint_properties friction="0.0"/>
</joint>

<joint name="upperleg_z_r" type="revolute">
<origin xyz="-9.99201e-15 0.142 -0.0175" rpy="-1.5708 1.15338e-14 7.69755e-15" />
<parent link="upperlegy" />
<child link="upperlegz" />
<axis xyz="0 0 1"/>
<limit effort="1" velocity="20" lower="-0.785398" upper="0.785398"/>
<joint_properties friction="0.0"/>
</joint>

<joint name="upperleg_y_r" type="revolute">
<origin xyz="-0.0175 -5.52336e-15 -0.052" rpy="-3.14159 1.5708 0" />
<parent link="upperlegx" />
<child link="upperlegy" />
<axis xyz="0 0 1"/>
<limit effort="1" velocity="20" lower="-1.0472" upper="0.261799"/>
<joint_properties friction="0.0"/>
</joint>

<joint name="upperleg_x_r" type="revolute">
<origin xyz="0.083 2.90452e-17 -0.056" rpy="1.5708 -1.06581e-14 -1.5708" />
<parent link="base" />
<child link="upperlegx" />
<axis xyz="0 0 1"/>
<limit effort="1" velocity="20" lower="-1.5708" upper="1.5708"/>
<joint_properties friction="0.0"/>
</joint>

<link name="upperlegx_2">
<!-- Shapes for cycloidal_disk -->
<!-- Shapes for part_2 -->
<collision>
<origin xyz="0.0255 -2.6229e-16 -0.052" rpy="-1.5708 2.15336e-14 1.5708" />
<geometry>
<cylinder length="0.022" radius="0.036" />
</geometry>
</collision>
<!-- Shapes for cycloidal_disk -->
<!-- Shapes for part_1 -->
<collision>
<origin xyz="0.0315 1.06598e-15 -0.052" rpy="-1.5708 -2.00309e-15 1.5708" />
<geometry>
<cylinder length="0.018" radius="0.024" />
</geometry>
</collision>
<!-- Shapes for housing -->
<collision>
<origin xyz="-0.0005 2.08167e-17 -0.052" rpy="1.5708 -2.33616e-15 1.5708" />
<geometry>
<cylinder length="0.02" radius="0.045" />
</geometry>
</collision>
<!-- Shapes for motor_shell -->
<collision>
<origin xyz="0.0305 2.08167e-17 -0.052" rpy="1.5708 -2.33616e-15 1.5708" />
<geometry>
<cylinder length="0.03" radius="0.045" />
</geometry>
</collision>
<!-- Shapes for housing -->
<collision>
<origin xyz="-0.0005 2.08167e-17 -0.052" rpy="1.5708 -2.33616e-15 1.5708" />
<geometry>
<cylinder length="0.02" radius="0.045" />
</geometry>
</collision>
<!-- Shapes for housing -->
<collision>
<origin xyz="-0.0005 2.08167e-17 -0.052" rpy="1.5708 -2.33616e-15 1.5708" />
<geometry>
<cylinder length="0.02" radius="0.045" />
</geometry>
</collision>
<visual>
<origin xyz="0 0 0" rpy="0 -0 0" />
<geometry>
<mesh filename="package:///upperlegx_2_visual.stl"/>
</geometry>
<material name="upperlegx_2_material">
<color rgba="0.8 0.8 0.8 1.0"/>
</material>
</visual>
<collision>
<origin xyz="0 0 0" rpy="0 -0 0" />
<geometry>
<mesh filename="package:///upperlegx_2_collision.stl"/>
</geometry>
<material name="upperlegx_2_material">
<color rgba="0.5 0.5 0.5 1.0"/>
</material>
</collision>
<inertial>
<origin xyz="0.0134137 -2.72624e-09 -0.0503059" rpy="0 0 0"/>
<mass value="0.732188" />
<inertia ixx="0.000759087" ixy="1.06686e-07"  ixz="1.66386e-05" iyy="0.000618258" iyz="-1.55325e-11" izz="0.000568045" />
</inertial>
</link>

<link name="upperlegy_2">
<!-- Shapes for motor_shell -->
<collision>
<origin xyz="-2.11616e-15 0.094 -0.0175" rpy="1.5708 7.88861e-31 7.69755e-15" />
<geometry>
<cylinder length="0.03" radius="0.045" />
</geometry>
</collision>
<!-- Shapes for part_2 -->
<collision>
<origin xyz="-2.14008e-15 0.099 -0.0175" rpy="-1.5708 -2.43677e-15 7.69755e-15" />
<geometry>
<cylinder length="0.022" radius="0.036" />
</geometry>
</collision>
<!-- Shapes for housing -->
<collision>
<origin xyz="-2.35478e-15 0.125 -0.0175" rpy="1.5708 7.88861e-31 7.69755e-15" />
<geometry>
<cylinder length="0.02" radius="0.045" />
</geometry>
</collision>
<!-- Shapes for housing -->
<collision>
<origin xyz="-2.35478e-15 0.125 -0.0175" rpy="1.5708 7.88861e-31 7.69755e-15" />
<geometry>
<cylinder length="0.02" radius="0.045" />
</geometry>
</collision>
<!-- Shapes for cycloidal_disk -->
<!-- Shapes for cycloidal_disk -->
<!-- Shapes for part_1 -->
<collision>
<origin xyz="-2.09543e-15 0.093 -0.0175" rpy="-1.5708 7.88861e-31 7.69755e-15" />
<geometry>
<cylinder length="0.018" radius="0.024" />
</geometry>
</collision>
<!-- Shapes for housing -->
<collision>
<origin xyz="-2.35478e-15 0.125 -0.0175" rpy="1.5708 7.88861e-31 7.69755e-15" />
<geometry>
<cylinder length="0.02" radius="0.045" />
</geometry>
</collision>
<visual>
<origin xyz="0 0 0" rpy="0 -0 0" />
<geometry>
<mesh filename="package:///upperlegy_2_visual.stl"/>
</geometry>
<material name="upperlegy_2_material">
<color rgba="0.8 0.8 0.8 1.0"/>
</material>
</visual>
<collision>
<origin xyz="0 0 0" rpy="0 -0 0" />
<geometry>
<mesh filename="package:///upperlegy_2_collision.stl"/>
</geometry>
<material name="upperlegy_2_material">
<color rgba="0.5 0.5 0.5 1.0"/>
</material>
</collision>
<inertial>
<origin xyz="-3.43845e-09 0.109524 -0.0175" rpy="0 0 0"/>
<mass value="0.65579" />
<inertia ixx="0.000501677" ixy="-1.06691e-07"  ixz="-1.61313e-12" iyy="0.000618053" iyz="2.08745e-12" izz="0.000501763" />
</inertial>
</link>

<link name="upperlegz_copy_1">
<!-- Shapes for extrusion__length_0.2+meter -->
<collision>
<origin xyz="-0.02 -4.996e-18 0.108" rpy="3.14159 -1.5708 0" />
<geometry>
<box size="0.2 0.02 0.02" />
</geometry>
</collision>
<!-- Shapes for cycloidal_disk -->
<!-- Shapes for housing -->
<collision>
<origin xyz="-0.02 -4.996e-18 0.288" rpy="3.14159 -1.5708 0" />
<geometry>
<cylinder length="0.02" radius="0.045" />
</geometry>
</collision>
<!-- Shapes for part_2 -->
<collision>
<origin xyz="0.006 -1.6605e-17 0.288" rpy="-4.39913e-16 -1.5708 0" />
<geometry>
<cylinder length="0.022" radius="0.036" />
</geometry>
</collision>
<!-- Shapes for part_1 -->
<collision>
<origin xyz="0.012 -3.30846e-17 0.288" rpy="-4.44089e-16 -1.5708 0" />
<geometry>
<cylinder length="0.018" radius="0.024" />
</geometry>
</collision>
<!-- Shapes for housing -->
<collision>
<origin xyz="-0.02 -4.996e-18 0.288" rpy="3.14159 -1.5708 0" />
<geometry>
<cylinder length="0.02" radius="0.045" />
</geometry>
</collision>
<!-- Shapes for housing -->
<collision>
<origin xyz="-0.02 -4.996e-18 0.288" rpy="3.14159 -1.5708 0" />
<geometry>
<cylinder length="0.02" radius="0.045" />
</geometry>
</collision>
<!-- Shapes for motor_shell -->
<collision>
<origin xyz="0.011 -1.87628e-17 0.288" rpy="3.14159 -1.5708 0" />
<geometry>
<cylinder length="0.03" radius="0.045" />
</geometry>
</collision>
<!-- Shapes for extrusion__length_0.2+meter -->
<collision>
<origin xyz="0.02 4.996e-18 0.108" rpy="3.14159 -1.5708 0" />
<geometry>
<box size="0.2 0.02 0.02" />
</geometry>
</collision>
<!-- Shapes for cycloidal_disk -->
<visual>
<origin xyz="0 0 0" rpy="0 -0 0" />
<geometry>
<mesh filename="package:///upperlegz_copy_1_visual.stl"/>
</geometry>
<material name="upperlegz_copy_1_material">
<color rgba="0.8 0.8 0.8 1.0"/>
</material>
</visual>
<collision>
<origin xyz="0 0 0" rpy="0 -0 0" />
<geometry>
<mesh filename="package:///upperlegz_copy_1_collision.stl"/>
</geometry>
<material name="upperlegz_copy_1_material">
<color rgba="0.5 0.5 0.5 1.0"/>
</material>
</collision>
<inertial>
<origin xyz="-0.00580914 -0.000686366 0.226874" rpy="0 0 0"/>
<mass value="1.07815" />
<inertia ixx="0.0108106" ixy="-1.34037e-05"  ixz="0.000206512" iyy="0.0107895" iyz="5.82772e-07" izz="0.000764981" />
</inertial>
</link>

<link name="lowerlegx_2">
<!-- Shapes for cycloidal_disk -->
<!-- Shapes for housing -->
<collision>
<origin xyz="-5.77316e-18 0.123 0.037" rpy="1.5708 1.5708 0" />
<geometry>
<cylinder length="0.02" radius="0.045" />
</geometry>
</collision>
<!-- Shapes for housing -->
<collision>
<origin xyz="-5.77316e-18 0.123 0.037" rpy="1.5708 1.5708 0" />
<geometry>
<cylinder length="0.02" radius="0.045" />
</geometry>
</collision>
<!-- Shapes for housing -->
<collision>
<origin xyz="-5.77316e-18 0.123 0.037" rpy="1.5708 1.5708 0" />
<geometry>
<cylinder length="0.02" radius="0.045" />
</geometry>
</collision>
<!-- Shapes for cycloidal_disk -->
<!-- Shapes for motor_shell -->
<collision>
<origin xyz="-5.77316e-18 0.092 0.037" rpy="1.5708 1.5708 0" />
<geometry>
<cylinder length="0.03" radius="0.045" />
</geometry>
</collision>
<visual>
<origin xyz="0 0 0" rpy="0 -0 0" />
<geometry>
<mesh filename="package:///lowerlegx_2_visual.stl"/>
</geometry>
<material name="lowerlegx_2_material">
<color rgba="0.8 0.8 0.8 1.0"/>
</material>
</visual>
<collision>
<origin xyz="0 0 0" rpy="0 -0 0" />
<geometry>
<mesh filename="package:///lowerlegx_2_collision.stl"/>
</geometry>
<material name="lowerlegx_2_material">
<color rgba="0.5 0.5 0.5 1.0"/>
</material>
</collision>
<inertial>
<origin xyz="-3.08432e-11 0.0901691 0.0312672" rpy="0 0 0"/>
<mass value="0.371026" />
<inertia ixx="0.000562525" ixy="2.2725e-12"  ixz="-5.15705e-09" iyy="0.000284979" iyz="-0.000126255" izz="0.000498725" />
</inertial>
</link>

<link name="lowerlegz_2">
<!-- Shapes for cycloidal_disk -->
<!-- Shapes for housing -->
<collision>
<origin xyz="-0.0015 -1.91431e-17 -0.2" rpy="-3.14159 1.5708 0" />
<geometry>
<cylinder length="0.02" radius="0.045" />
</geometry>
</collision>
<!-- Shapes for housing -->
<collision>
<origin xyz="-0.0015 -1.91431e-17 -0.2" rpy="-3.14159 1.5708 0" />
<geometry>
<cylinder length="0.02" radius="0.045" />
</geometry>
</collision>
<!-- Shapes for housing -->
<collision>
<origin xyz="-0.0015 -1.91431e-17 -0.2" rpy="-3.14159 1.5708 0" />
<geometry>
<cylinder length="0.02" radius="0.045" />
</geometry>
</collision>
<!-- Shapes for extrusion__length_0.15+meter -->
<collision>
<origin xyz="-5.98019e-31 -1.13643e-17 -0.085" rpy="-1.2326e-31 1.5708 0" />
<geometry>
<box size="0.15 0.02 0.02" />
</geometry>
</collision>
<!-- Shapes for motor_shell -->
<collision>
<origin xyz="-0.0325 -1.19472e-19 -0.2" rpy="-3.14159 1.5708 0" />
<geometry>
<cylinder length="0.03" radius="0.045" />
</geometry>
</collision>
<!-- Shapes for cycloidal_disk -->
<visual>
<origin xyz="0 0 0" rpy="0 -0 0" />
<geometry>
<mesh filename="package:///lowerlegz_2_visual.stl"/>
</geometry>
<material name="lowerlegz_2_material">
<color rgba="0.8 0.8 0.8 1.0"/>
</material>
</visual>
<collision>
<origin xyz="0 0 0" rpy="0 -0 0" />
<geometry>
<mesh filename="package:///lowerlegz_2_collision.stl"/>
</geometry>
<material name="lowerlegz_2_material">
<color rgba="0.5 0.5 0.5 1.0"/>
</material>
</collision>
<inertial>
<origin xyz="-0.0111152 -7.92858e-12 -0.158926" rpy="0 0 0"/>
<mass value="0.457786" />
<inertia ixx="0.00222732" ixy="-2.17139e-12"  ixz="-0.000217459" iyy="0.00224323" iyz="5.16092e-09" izz="0.000243554" />
</inertial>
</link>

<link name="feetx_copy_1">
<visual>
<origin xyz="0 0 0" rpy="0 -0 0" />
<geometry>
<mesh filename="package:///feetx_copy_1_visual.stl"/>
</geometry>
<material name="feetx_copy_1_material">
<color rgba="0.8 0.8 0.8 1.0"/>
</material>
</visual>
<collision>
<origin xyz="0 0 0" rpy="0 -0 0" />
<geometry>
<mesh filename="package:///feetx_copy_1_collision.stl"/>
</geometry>
<material name="feetx_copy_1_material">
<color rgba="0.5 0.5 0.5 1.0"/>
</material>
</collision>
<inertial>
<origin xyz="0.0223276 0.0258701 0.00228742" rpy="0 0 0"/>
<mass value="0.0599594" />
<inertia ixx="3.79265e-05" ixy="-1.67086e-05"  ixz="-8.09384e-06" iyy="3.35014e-05" iyz="-5.30579e-06" izz="5.5539e-05" />
</inertial>
</link>

<link name="feety_2">
<!-- Shapes for housing -->
<collision>
<origin xyz="0 -2.36658e-32 -0.017" rpy="3.14159 -2.22045e-16 7.26717e-31" />
<geometry>
<cylinder length="0.02" radius="0.045" />
</geometry>
</collision>
<!-- Shapes for housing -->
<collision>
<origin xyz="0 -2.36658e-32 -0.017" rpy="3.14159 -2.22045e-16 7.26717e-31" />
<geometry>
<cylinder length="0.02" radius="0.045" />
</geometry>
</collision>
<!-- Shapes for cycloidal_disk -->
<!-- Shapes for cycloidal_disk -->
<!-- Shapes for motor_shell -->
<collision>
<origin xyz="0 -7.25752e-32 -0.048" rpy="3.14159 -2.22045e-16 7.26717e-31" />
<geometry>
<cylinder length="0.03" radius="0.045" />
</geometry>
</collision>
<!-- Shapes for housing -->
<collision>
<origin xyz="0 -2.36658e-32 -0.017" rpy="3.14159 -2.22045e-16 7.26717e-31" />
<geometry>
<cylinder length="0.02" radius="0.045" />
</geometry>
</collision>
<visual>
<origin xyz="0 0 0" rpy="0 -0 0" />
<geometry>
<mesh filename="package:///feety_2_visual.stl"/>
</geometry>
<material name="feety_2_material">
<color rgba="0.8 0.8 0.8 1.0"/>
</material>
</visual>
<collision>
<origin xyz="0 0 0" rpy="0 -0 0" />
<geometry>
<mesh filename="package:///feety_2_collision.stl"/>
</geometry>
<material name="feety_2_material">
<color rgba="0.5 0.5 0.5 1.0"/>
</material>
</collision>
<inertial>
<origin xyz="-1.15671e-09 0.0251333 -0.0557187" rpy="0 0 0"/>
<mass value="1.93667" />
<inertia ixx="0.0122302" ixy="-5.21342e-09"  ixz="-3.90299e-08" iyy="0.0123883" iyz="-0.00171265" izz="0.00277728" />
</inertial>
</link>

<joint name="feet_y_l" type="revolute">
<origin xyz="0.048 0.0398251 0.0140842" rpy="2.05391e-15 -1.5708 0" />
<parent link="feetx_copy_1" />
<child link="feety_2" />
<axis xyz="0 0 1"/>
<limit effort="1" velocity="20" lower="-0.261799" upper="0.261799"/>
<joint_properties friction="0.0"/>
</joint>

<joint name="feet_x_l" type="revolute">
<origin xyz="0.0155 -1.48094e-17 -0.2" rpy="-1.5708 -2.95823e-30 1.5708" />
<parent link="lowerlegz_2" />
<child link="feetx_copy_1" />
<axis xyz="0 0 1"/>
<limit effort="1" velocity="20" lower="-0.785398" upper="0.785398"/>
<joint_properties friction="0.0"/>
</joint>

<joint name="lowerleg_z_l" type="revolute">
<origin xyz="6.96665e-17 0.14 0.037" rpy="1.5708 -1.5708 0" />
<parent link="lowerlegx_2" />
<child link="lowerlegz_2" />
<axis xyz="0 0 1"/>
<limit effort="1" velocity="20" lower="-0.785398" upper="0.785398"/>
<joint_properties friction="0.0"/>
</joint>

<joint name="lowerleg_x_l" type="revolute">
<origin xyz="-0.037 -2.52021e-17 0.288" rpy="1.5708 4.44089e-16 1.5708" />
<parent link="upperlegz_copy_1" />
<child link="lowerlegx_2" />
<axis xyz="0 0 1"/>
<limit effort="1" velocity="20" lower="-1.74533" upper="0.174533"/>
<joint_properties friction="0.0"/>
</joint>

<joint name="upperleg_z_l" type="revolute">
<origin xyz="-2.47025e-15 0.142 -0.0175" rpy="-1.5708 -2.15921e-15 7.69755e-15" />
<parent link="upperlegy_2" />
<child link="upperlegz_copy_1" />
<axis xyz="0 0 1"/>
<limit effort="1" velocity="20" lower="-0.785398" upper="0.785398"/>
<joint_properties friction="0.0"/>
</joint>

<joint name="upperleg_y_l" type="revolute">
<origin xyz="-0.0175 1.38778e-17 -0.052" rpy="6.12323e-17 -1.5708 0" />
<parent link="upperlegx_2" />
<child link="upperlegy_2" />
<axis xyz="0 0 1"/>
<limit effort="1" velocity="20" lower="-0.261799" upper="1.0472"/>
<joint_properties friction="0.0"/>
</joint>

<joint name="upperleg_x_l" type="revolute">
<origin xyz="-0.083 -1.69021e-17 -0.056" rpy="-1.5708 -3.77261e-29 -1.5708" />
<parent link="base" />
<child link="upperlegx_2" />
<axis xyz="0 0 1"/>
<limit effort="1" velocity="20" lower="-1.5708" upper="1.5708"/>
<joint_properties friction="0.0"/>
</joint>


</robot>
