<robot name="humanoid_v1">
<link name="base_link"></link>
<joint name="base_link_to_base" type="fixed">
<parent link="base_link"/>
<child link="base" />
<origin rpy="0.0 0 0" xyz="0 0 0"/>
</joint>
<link name="base">
<visual>
<origin xyz="0 0 0" rpy="0 -0 0" />
<geometry>
<mesh filename="package:///base_visual.stl"/>
</geometry>
<material name="base_material">
<color rgba="0.8 0.8 0.8 1.0"/>
</material>
</visual>
<collision>
<origin xyz="0 0 0" rpy="0 -0 0" />
<geometry>
<mesh filename="package:///base_collision.stl"/>
</geometry>
<material name="base_material">
<color rgba="0.5 0.5 0.5 1.0"/>
</material>
</collision>
<inertial>
<origin xyz="7.3655e-18 -0.010053 -0.00364106" rpy="0 0 0"/>
<mass value="2.09484" />
<inertia ixx="0.0277752" ixy="4.21566e-12"  ixz="2.80707e-18" iyy="0.0322146" iyz="0.00449915" izz="0.00921242" />
</inertial>
</link>

<link name="upperlegx">
<visual>
<origin xyz="0 0 0" rpy="0 -0 0" />
<geometry>
<mesh filename="package:///upperlegx_visual.stl"/>
</geometry>
<material name="upperlegx_material">
<color rgba="0.8 0.8 0.8 1.0"/>
</material>
</visual>
<collision>
<origin xyz="0 0 0" rpy="0 -0 0" />
<geometry>
<mesh filename="package:///upperlegx_collision.stl"/>
</geometry>
<material name="upperlegx_material">
<color rgba="0.5 0.5 0.5 1.0"/>
</material>
</collision>
<inertial>
<origin xyz="0.0134137 -2.72625e-09 -0.0503059" rpy="0 0 0"/>
<mass value="0.732188" />
<inertia ixx="0.000759087" ixy="1.06686e-07"  ixz="1.66386e-05" iyy="0.000618258" iyz="-1.55325e-11" izz="0.000568045" />
</inertial>
</link>

<link name="upperlegy">
<visual>
<origin xyz="0 0 0" rpy="0 -0 0" />
<geometry>
<mesh filename="package:///upperlegy_visual.stl"/>
</geometry>
<material name="upperlegy_material">
<color rgba="0.8 0.8 0.8 1.0"/>
</material>
</visual>
<collision>
<origin xyz="0 0 0" rpy="0 -0 0" />
<geometry>
<mesh filename="package:///upperlegy_collision.stl"/>
</geometry>
<material name="upperlegy_material">
<color rgba="0.5 0.5 0.5 1.0"/>
</material>
</collision>
<inertial>
<origin xyz="-3.43844e-09 0.109524 -0.0175" rpy="0 0 0"/>
<mass value="0.65579" />
<inertia ixx="0.000501677" ixy="-1.06691e-07"  ixz="-1.61313e-12" iyy="0.000618053" iyz="2.08745e-12" izz="0.000501763" />
</inertial>
</link>

<link name="upperlegz">
<visual>
<origin xyz="0 0 0" rpy="0 -0 0" />
<geometry>
<mesh filename="package:///upperlegz_visual.stl"/>
</geometry>
<material name="upperlegz_material">
<color rgba="0.8 0.8 0.8 1.0"/>
</material>
</visual>
<collision>
<origin xyz="0 0 0" rpy="0 -0 0" />
<geometry>
<mesh filename="package:///upperlegz_collision.stl"/>
</geometry>
<material name="upperlegz_material">
<color rgba="0.5 0.5 0.5 1.0"/>
</material>
</collision>
<inertial>
<origin xyz="0.00580914 -0.000686366 0.226874" rpy="0 0 0"/>
<mass value="1.07815" />
<inertia ixx="0.0108106" ixy="1.34037e-05"  ixz="-0.000206513" iyy="0.0107895" iyz="5.82774e-07" izz="0.000764981" />
</inertial>
</link>

<joint name="upperleg_z_r" type="revolute">
<origin xyz="-5.27356e-16 0.142 -0.0175" rpy="-1.5708 -1.65983e-14 7.69755e-15" />
<parent link="upperlegy" />
<child link="upperlegz" />
<axis xyz="0 0 1"/>
<limit effort="1" velocity="20" lower="-1.5708" upper="1.5708"/>
<joint_properties friction="0.0"/>
</joint>

<joint name="upperleg_y_r" type="revolute">
<origin xyz="-0.0175 -4.54498e-15 -0.052" rpy="-3.14159 1.5708 0" />
<parent link="upperlegx" />
<child link="upperlegy" />
<axis xyz="0 0 1"/>
<limit effort="1" velocity="20" lower="-6.28319" upper="6.28319"/>
<joint_properties friction="0.0"/>
</joint>

<joint name="upperleg_x_r" type="revolute">
<origin xyz="0.083 2.90452e-17 -0.056" rpy="1.5708 -3.55271e-15 -1.5708" />
<parent link="base" />
<child link="upperlegx" />
<axis xyz="0 0 1"/>
<limit effort="1" velocity="20" lower="-6.28319" upper="6.28319"/>
<joint_properties friction="0.0"/>
</joint>

<link name="upperlegx_2">
<visual>
<origin xyz="0 0 0" rpy="0 -0 0" />
<geometry>
<mesh filename="package:///upperlegx_2_visual.stl"/>
</geometry>
<material name="upperlegx_2_material">
<color rgba="0.8 0.8 0.8 1.0"/>
</material>
</visual>
<collision>
<origin xyz="0 0 0" rpy="0 -0 0" />
<geometry>
<mesh filename="package:///upperlegx_2_collision.stl"/>
</geometry>
<material name="upperlegx_2_material">
<color rgba="0.5 0.5 0.5 1.0"/>
</material>
</collision>
<inertial>
<origin xyz="0.0134137 -2.72624e-09 -0.0503059" rpy="0 0 0"/>
<mass value="0.732188" />
<inertia ixx="0.000759087" ixy="1.06686e-07"  ixz="1.66386e-05" iyy="0.000618258" iyz="-1.55325e-11" izz="0.000568045" />
</inertial>
</link>

<link name="upperlegy_2">
<visual>
<origin xyz="0 0 0" rpy="0 -0 0" />
<geometry>
<mesh filename="package:///upperlegy_2_visual.stl"/>
</geometry>
<material name="upperlegy_2_material">
<color rgba="0.8 0.8 0.8 1.0"/>
</material>
</visual>
<collision>
<origin xyz="0 0 0" rpy="0 -0 0" />
<geometry>
<mesh filename="package:///upperlegy_2_collision.stl"/>
</geometry>
<material name="upperlegy_2_material">
<color rgba="0.5 0.5 0.5 1.0"/>
</material>
</collision>
<inertial>
<origin xyz="-3.43844e-09 0.109524 -0.0175" rpy="0 0 0"/>
<mass value="0.65579" />
<inertia ixx="0.000501677" ixy="-1.06691e-07"  ixz="-1.61313e-12" iyy="0.000618053" iyz="2.08745e-12" izz="0.000501763" />
</inertial>
</link>

<link name="upperlegz_copy_1">
<visual>
<origin xyz="0 0 0" rpy="0 -0 0" />
<geometry>
<mesh filename="package:///upperlegz_copy_1_visual.stl"/>
</geometry>
<material name="upperlegz_copy_1_material">
<color rgba="0.8 0.8 0.8 1.0"/>
</material>
</visual>
<collision>
<origin xyz="0 0 0" rpy="0 -0 0" />
<geometry>
<mesh filename="package:///upperlegz_copy_1_collision.stl"/>
</geometry>
<material name="upperlegz_copy_1_material">
<color rgba="0.5 0.5 0.5 1.0"/>
</material>
</collision>
<inertial>
<origin xyz="-0.00580914 -0.000686366 0.226874" rpy="0 0 0"/>
<mass value="1.07815" />
<inertia ixx="0.0108106" ixy="-1.34037e-05"  ixz="0.000206512" iyy="0.0107895" iyz="5.82772e-07" izz="0.000764981" />
</inertial>
</link>

<joint name="upperleg_z_l" type="revolute">
<origin xyz="-4.71845e-16 0.142 -0.0175" rpy="-1.5708 -2.15921e-15 7.69755e-15" />
<parent link="upperlegy_2" />
<child link="upperlegz_copy_1" />
<axis xyz="0 0 1"/>
<limit effort="1" velocity="20" lower="-1.5708" upper="1.5708"/>
<joint_properties friction="0.0"/>
</joint>

<joint name="upperleg_y_l" type="revolute">
<origin xyz="-0.0175 -4.16334e-17 -0.052" rpy="6.12323e-17 -1.5708 0" />
<parent link="upperlegx_2" />
<child link="upperlegy_2" />
<axis xyz="0 0 1"/>
<limit effort="1" velocity="20" lower="-6.28319" upper="6.28319"/>
<joint_properties friction="0.0"/>
</joint>

<joint name="upperleg_x_l" type="revolute">
<origin xyz="-0.083 -1.69021e-17 -0.056" rpy="-1.5708 -3.77261e-29 -1.5708" />
<parent link="base" />
<child link="upperlegx_2" />
<axis xyz="0 0 1"/>
<limit effort="1" velocity="20" lower="-6.28319" upper="6.28319"/>
<joint_properties friction="0.0"/>
</joint>


</robot>
